<?xml version="1.0"?>

<robot name="UMARU" xmlns:xacro="http://www.ros.org/wiki/xacro">
  <xacro:property name="scale" value="1"/>

  <material name="cyan">
    <color rgba="0 255 255 1"/>
  </material>

  <material name="yellow">
    <color rgba="255 255 0 1"/>
  </material>

  <link name="world"></link>

  <link name="body">
    <visual>
      <geometry>
        <box size="${scale * 0.147}  ${scale * 0.117} ${scale * 0.176124}"/>
      </geometry>
      <origin rpy="0 0 1.57079632679"/>
      <material name="cyan"/>
    </visual>
    <collision>
      <geometry>
        <box size="${scale * 0.147}  ${scale * 0.117} ${scale * 0.176124}"/>
      </geometry>
      <origin rpy="0 0 1.57079632679"/>
    </collision>
  </link>
  <joint name="body_with_world" type="fixed">
    <parent link="world"/>
    <child link="body"/>
  </joint>

  <link name="right_shoulder_horizontal">
    <visual>
      <geometry>
        <box size="${scale * 0.055} ${scale * 0.065} ${scale * 0.030}"/>
      </geometry>
      <origin rpy="0 0 1.57079632679" xyz="0 0 0"/>
      <material name="yellow"/>
    </visual>
    <collision>
      <geometry>
        <box size="${scale * 0.055} ${scale * 0.065} ${scale * 0.030}"/>
      </geometry>
      <origin rpy="0 0 1.57079632679" xyz="0 0 0"/>
    </collision>
  </link>
  <joint name="R_SHO_PITCH" type="fixed"> <!-- JOINT_ID = 1 -->
    <axis xyz="0 1 0"/>
    <parent link="body"/>
    <child link="right_shoulder_horizontal"/>
    <origin xyz="${scale * -0.0027} ${scale * -0.101} ${scale * 0.064061}"/>
  </joint>

  <link name="left_shoulder_horizontal">
    <visual>
      <geometry>
        <box size="${scale * 0.055} ${scale * 0.065} ${scale * 0.030}"/>
      </geometry>
      <origin rpy="0 0 1.57079632679" xyz="0 0 0"/>
      <material name="yellow"/>
    </visual>
    <collision>
      <geometry>
        <box size="${scale * 0.055} ${scale * 0.065} ${scale * 0.030}"/>
      </geometry>
      <origin rpy="0 0 1.57079632679" xyz="0 0 0"/>
    </collision>
  </link>
  <joint name="L_SHO_PITCH" type="continuous"> <!-- JOINT_ID = 2 -->
    <axis xyz="0 1 0"/>
    <parent link="body"/>
    <child link="left_shoulder_horizontal"/>
    <origin xyz="${scale * 0.0027} ${scale * 0.101} ${scale * 0.064061}"/>
  </joint>

  <link name="right_shoulder_vertical">
    <visual>
      <geometry>
        <box size="${scale * 0.030} ${scale * 0.065} ${scale * 0.020}"/>
      </geometry>
      <origin rpy="0 0 1.57079632679" xyz="0 0 0"/>
      <material name="yellow"/>
    </visual>
    <collision>
      <geometry>
        <box size="${scale * 0.030} ${scale * 0.065} ${scale * 0.020}"/>
      </geometry>
      <origin rpy="0 0 1.57079632679" xyz="0 0 0"/>
    </collision>
  </link>

  <link name="right_arm">
    <visual>
      <geometry>
        <box size="${scale * 0.0402} ${scale * 0.038} ${scale * 0.156}"/>
      </geometry>
      <origin rpy="0 0 1.57079632679" xyz="0 0 0"/> 
      <material name="cyan"/>
    </visual>
    <collision>
      <geometry>
        <box size="${scale * 0.0402} ${scale * 0.038} ${scale * 0.156}"/>
      </geometry>
      <origin rpy="0 0 1.57079632679" xyz="0 0 0"/>
    </collision>
  </link>
  <!-- TODO: Type should be revolute -->
  <joint name="R_SHO_ROLL" type="continuous"> <!-- JOINT_ID = 3 -->
    <axis xyz="1 0 0"/>
    <parent link="right_shoulder_vertical"/>
    <child link="right_arm"/>
    <origin xyz="0 0 ${scale * -0.084}"/>
  </joint>

  <link name="left_shoulder_vertical">
    <visual>
      <geometry>
        <box size="${scale * 0.030} ${scale * 0.065} ${scale * 0.020}"/>
      </geometry>
      <origin rpy="0 0 1.57079632679" xyz="0 0 0"/>
      <material name="yellow"/>
    </visual>
    <collision>
      <geometry>
        <box size="${scale * 0.030} ${scale * 0.065} ${scale * 0.020}"/>
      </geometry>
      <origin rpy="0 0 1.57079632679" xyz="0 0 0"/>
    </collision>
  </link>

  <link name="left_arm">
    <visual>
      <geometry>
        <box size="${scale * 0.0402} ${scale * 0.038} ${scale * 0.156}"/>
      </geometry>
      <origin rpy="0 0 1.57079632679" xyz="0 0 0"/>
      <material name="cyan"/>
    </visual>
    <collision>
      <geometry>
        <box size="${scale * 0.0402} ${scale * 0.038} ${scale * 0.156}"/>
      </geometry>
      <origin rpy="0 0 1.57079632679" xyz="0 0 0"/>
    </collision>
  </link>
  <!-- TODO: Type should be revolute -->
  <joint name="L_SHO_ROLL" type="fixed"> <!-- JOINT_ID = 4 -->
    <parent link="left_shoulder_vertical"/>
    <child link="left_arm"/>
    <origin xyz="0 0 ${scale * -0.084}"/>
  </joint>

  <link name="right_hand">
    <visual>
      <geometry>
        <box size="${scale * 0.0505} ${scale * 0.0276} ${scale * 0.162}"/>
      </geometry>
      <origin rpy="0 0 1.57079632679" xyz="0 0 ${scale * -0.081}"/>
      <material name="yellow"/>
    </visual>
    <collision>
      <geometry>
        <box size="${scale * 0.0505} ${scale * 0.0276} ${scale * 0.162}"/>
      </geometry>
      <origin rpy="0 0 1.57079632679" xyz="0 0 ${scale * -0.081}"/>
    </collision>
  </link>
  <joint name="R_ELBOW" type="revolute"> <!-- JOINT_ID = 5 -->
    <axis xyz="0 1 0"/>
    <limit effort="1000.0" lower="-2.35619" upper="2.35619" velocity="0.5"/>
    <parent link="right_arm"/>
    <child link="right_hand"/>
    <origin xyz="0 0 ${scale * -0.065}"/>
  </joint>

  <link name="left_hand">
    <visual>
      <geometry>
        <box size="${scale * 0.0505} ${scale * 0.0276} ${scale * 0.162}"/>
      </geometry>
      <origin rpy="0 0 1.57079632679" xyz="0 0 ${scale * -0.081}"/>
      <material name="yellow"/>
    </visual>
    <collision>
      <geometry>
        <box size="${scale * 0.0505} ${scale * 0.0276} ${scale * 0.162}"/>
      </geometry>
      <origin rpy="0 0 1.57079632679" xyz="0 0 ${scale * -0.081}"/>
    </collision>
  </link>
  <joint name="L_ELBOW" type="revolute"> <!-- JOINT_ID = 6 -->
    <axis xyz="0 1 0"/>
    <limit effort="1000.0" lower="-2.35619" upper="2.35619" velocity="0.5"/>
    <parent link="left_arm"/>
    <child link="left_hand"/>
    <origin xyz="0 0 ${scale * -0.065}"/>
  </joint>

  <joint name="RIGHT_SHO" type="fixed">
    <parent link="right_shoulder_horizontal"/>
    <child link="right_shoulder_vertical"/>
    <origin xyz="0 ${scale * -0.0125} ${scale * -0.025}"/>
  </joint>

  <joint name="LEFT_SHO" type="fixed">
    <parent link="left_shoulder_horizontal"/>
    <child link="left_shoulder_vertical"/>
    <origin xyz="0 ${scale * 0.0125} ${scale * -0.025}"/>
  </joint>
  
  <link name="right_upper_leg">
    <visual>
      <geometry>
        <box size="${scale * 0.049} ${scale * 0.049} ${scale * 0.065520}"/>
      </geometry>
      <origin rpy="0 0 1.57079632679"/>
      <material name="yellow"/>
    </visual>
    <collision>
      <geometry>
        <box size="${scale * 0.049} ${scale * 0.049} ${scale * 0.065520}"/>
      </geometry>
      <origin rpy="0 0 1.57079632679"/>
    </collision>
  </link>
  <joint name="R_HIP_YAW" type="fixed">
    <parent link="body"/>
    <child link="right_upper_leg"/>
    <origin xyz="${scale * 0.034} ${scale * -0.049} ${scale * -0.120882}"/>
  </joint>
  
  <link name="left_upper_leg">
    <visual>
      <geometry>
        <box size="${scale * 0.049} ${scale * 0.049} ${scale * 0.065520}"/>
      </geometry>
      <origin rpy="0 0 1.57079632679"/>
      <material name="yellow"/>
    </visual>
    <collision>
      <geometry>
        <box size="${scale * 0.049} ${scale * 0.049} ${scale * 0.065520}"/>
      </geometry>
      <origin rpy="0 0 1.57079632679"/>
    </collision>
  </link>
  <joint name="L_HIP_YAW" type="fixed">
    <parent link="body"/>
    <child link="left_upper_leg"/>
    <origin xyz="${scale * 0.034} ${scale * 0.049} ${scale * -0.120882}"/>
  </joint>

</robot>